Traceback (most recent call last):
  File "/opt/hostedtoolcache/Python/3.11.11/x64/lib/python3.11/site-packages/jupyter_cache/executors/utils.py", line 58, in single_nb_execution
    executenb(
  File "/opt/hostedtoolcache/Python/3.11.11/x64/lib/python3.11/site-packages/nbclient/client.py", line 1319, in execute
    return NotebookClient(nb=nb, resources=resources, km=km, **kwargs).execute()
           ^^^^^^^^^^^^^^^^^^^^^^^^^^^^^^^^^^^^^^^^^^^^^^^^^^^^^^^^^^^^^^^^^^^^^
  File "/opt/hostedtoolcache/Python/3.11.11/x64/lib/python3.11/site-packages/jupyter_core/utils/__init__.py", line 165, in wrapped
    return loop.run_until_complete(inner)
           ^^^^^^^^^^^^^^^^^^^^^^^^^^^^^^
  File "/opt/hostedtoolcache/Python/3.11.11/x64/lib/python3.11/asyncio/base_events.py", line 654, in run_until_complete
    return future.result()
           ^^^^^^^^^^^^^^^
  File "/opt/hostedtoolcache/Python/3.11.11/x64/lib/python3.11/site-packages/nbclient/client.py", line 709, in async_execute
    await self.async_execute_cell(
  File "/opt/hostedtoolcache/Python/3.11.11/x64/lib/python3.11/site-packages/nbclient/client.py", line 1062, in async_execute_cell
    await self._check_raise_for_error(cell, cell_index, exec_reply)
  File "/opt/hostedtoolcache/Python/3.11.11/x64/lib/python3.11/site-packages/nbclient/client.py", line 918, in _check_raise_for_error
    raise CellExecutionError.from_cell_and_msg(cell, exec_reply_content)
nbclient.exceptions.CellExecutionError: An error occurred while executing the following cell:
------------------
# By convention, PyPSA is imported without an alias:
import pypsa

# Other dependencies
import pandas as pd
import geopandas as gpd
import matplotlib.pyplot as plt
import holoviews as hv
import hvplot.pandas
import cartopy.crs as ccrs
import folium
import mapclassify
from pypsa.plot.maps.static import (
    add_legend_circles,
    add_legend_patches,
    add_legend_lines,
)
from pathlib import Path

plt.style.use("bmh")
------------------


[31m---------------------------------------------------------------------------[39m
[31mModuleNotFoundError[39m                       Traceback (most recent call last)
[36mCell[39m[36m [39m[32mIn[2][39m[32m, line 13[39m
[32m     11[39m [38;5;28;01mimport[39;00m[38;5;250m [39m[34;01mfolium[39;00m
[32m     12[39m [38;5;28;01mimport[39;00m[38;5;250m [39m[34;01mmapclassify[39;00m
[32m---> [39m[32m13[39m [38;5;28;01mfrom[39;00m[38;5;250m [39m[34;01mpypsa[39;00m[34;01m.[39;00m[34;01mplot[39;00m[34;01m.[39;00m[34;01mmaps[39;00m[34;01m.[39;00m[34;01mstatic[39;00m[38;5;250m [39m[38;5;28;01mimport[39;00m (
[32m     14[39m     add_legend_circles,
[32m     15[39m     add_legend_patches,
[32m     16[39m     add_legend_lines,
[32m     17[39m )
[32m     18[39m [38;5;28;01mfrom[39;00m[38;5;250m [39m[34;01mpathlib[39;00m[38;5;250m [39m[38;5;28;01mimport[39;00m Path
[32m     20[39m plt.style.use([33m"[39m[33mbmh[39m[33m"[39m)

[31mModuleNotFoundError[39m: No module named 'pypsa.plot.maps.static'; 'pypsa.plot.maps' is not a package

